2019-06-18 22:20:17 WARNING (MainThread) [homeassistant.components.http] legacy_api_password support has been enabled. If you don't require it, remove the 'api_password' from your http config.
2019-06-18 22:20:42 ERROR (MainThread) [homeassistant.setup] Error during setup of component octoprint
Traceback (most recent call last):
  File "/srv/homeassistant/lib/python3.5/site-packages/homeassistant/setup.py", line 148, in _async_setup_component
    component.setup, hass, processed_config)  # type: ignore
  File "/usr/lib/python3.5/asyncio/futures.py", line 380, in __iter__
    yield self  # This tells Task to wait for completion.
  File "/usr/lib/python3.5/asyncio/tasks.py", line 304, in _wakeup
    future.result()
  File "/usr/lib/python3.5/asyncio/futures.py", line 293, in result
    raise self._exception
  File "/usr/lib/python3.5/concurrent/futures/thread.py", line 55, in run
    result = self.fn(*self.args, **self.kwargs)
  File "/srv/homeassistant/lib/python3.5/site-packages/homeassistant/components/octoprint.py", line 95, in setup
    for printer in config[DOMAIN]:
KeyError: 'octoprint'
2019-06-18 22:22:42 ERROR (MainThread) [homeassistant.core] Error executing service <ServiceCall tts.google_say (c:73ce88d163ce4b4a8eea3646228ef354): entity_id=['media_player.samsung_6_series_49_ue49mu6175'], message=Hello? Is this home?>
Traceback (most recent call last):
  File "/srv/homeassistant/lib/python3.5/site-packages/homeassistant/core.py", line 1177, in _event_to_service_call
    await service_handler.func(service_call)
  File "/srv/homeassistant/lib/python3.5/site-packages/homeassistant/components/tts/__init__.py", line 137, in async_say_handle
    options=options
  File "/srv/homeassistant/lib/python3.5/site-packages/homeassistant/components/tts/__init__.py", line 306, in async_get_url
    engine, key, message, use_cache, language, options)
  File "/srv/homeassistant/lib/python3.5/site-packages/homeassistant/components/tts/__init__.py", line 318, in async_get_tts_audio
    message, language, options)
  File "/srv/homeassistant/lib/python3.5/site-packages/homeassistant/components/tts/google.py", line 83, in async_get_tts_audio
    token.calculate_token, part)
  File "/usr/lib/python3.5/asyncio/futures.py", line 380, in __iter__
    yield self  # This tells Task to wait for completion.
  File "/usr/lib/python3.5/asyncio/tasks.py", line 304, in _wakeup
    future.result()
  File "/usr/lib/python3.5/asyncio/futures.py", line 293, in result
    raise self._exception
  File "/usr/lib/python3.5/concurrent/futures/thread.py", line 55, in run
    result = self.fn(*self.args, **self.kwargs)
  File "/srv/homeassistant/lib/python3.5/site-packages/gtts_token/gtts_token.py", line 28, in calculate_token
    seed = self._get_token_key()
  File "/srv/homeassistant/lib/python3.5/site-packages/gtts_token/gtts_token.py", line 57, in _get_token_key
    tkk_expr = re.search(".*?(TKK=.*?;)W.*?", line).group(1)
AttributeError: 'NoneType' object has no attribute 'group'
2019-06-18 22:23:23 ERROR (MainThread) [homeassistant.core] Error executing service <ServiceCall tts.google_say (c:f14f715347134a9b8bdc3f3ffcd26675): entity_id=['media_player.samsung_6_series_49_ue49mu6175'], message=I am robocop!>
Traceback (most recent call last):
  File "/srv/homeassistant/lib/python3.5/site-packages/homeassistant/core.py", line 1177, in _event_to_service_call
    await service_handler.func(service_call)
  File "/srv/homeassistant/lib/python3.5/site-packages/homeassistant/components/tts/__init__.py", line 137, in async_say_handle
    options=options
  File "/srv/homeassistant/lib/python3.5/site-packages/homeassistant/components/tts/__init__.py", line 306, in async_get_url
    engine, key, message, use_cache, language, options)
  File "/srv/homeassistant/lib/python3.5/site-packages/homeassistant/components/tts/__init__.py", line 318, in async_get_tts_audio
    message, language, options)
  File "/srv/homeassistant/lib/python3.5/site-packages/homeassistant/components/tts/google.py", line 83, in async_get_tts_audio
    token.calculate_token, part)
  File "/usr/lib/python3.5/asyncio/futures.py", line 380, in __iter__
    yield self  # This tells Task to wait for completion.
  File "/usr/lib/python3.5/asyncio/tasks.py", line 304, in _wakeup
    future.result()
  File "/usr/lib/python3.5/asyncio/futures.py", line 293, in result
    raise self._exception
  File "/usr/lib/python3.5/concurrent/futures/thread.py", line 55, in run
    result = self.fn(*self.args, **self.kwargs)
  File "/srv/homeassistant/lib/python3.5/site-packages/gtts_token/gtts_token.py", line 28, in calculate_token
    seed = self._get_token_key()
  File "/srv/homeassistant/lib/python3.5/site-packages/gtts_token/gtts_token.py", line 57, in _get_token_key
    tkk_expr = re.search(".*?(TKK=.*?;)W.*?", line).group(1)
AttributeError: 'NoneType' object has no attribute 'group'
2019-06-18 22:41:19 WARNING (MainThread) [homeassistant.components.http.ban] Login attempt or request with invalid authentication from 192.168.1.111
2019-06-18 22:43:28 WARNING (MainThread) [homeassistant.components.http.ban] Login attempt or request with invalid authentication from 192.168.1.111
2019-06-18 22:43:38 WARNING (MainThread) [homeassistant.components.http.ban] Login attempt or request with invalid authentication from 192.168.1.111
2019-06-18 22:43:50 WARNING (MainThread) [homeassistant.components.http.ban] Login attempt or request with invalid authentication from 192.168.1.111
2019-06-18 22:44:36 WARNING (MainThread) [homeassistant.components.http.ban] Login attempt or request with invalid authentication from 192.168.1.111
2019-06-18 22:44:53 WARNING (MainThread) [homeassistant.components.http.ban] Login attempt or request with invalid authentication from 192.168.1.111
2019-06-18 22:46:21 WARNING (MainThread) [homeassistant.components.http.ban] Login attempt or request with invalid authentication from 192.168.1.111
2019-06-18 22:46:25 WARNING (MainThread) [homeassistant.components.http.ban] Login attempt or request with invalid authentication from 192.168.1.111
